25-02-03 10:57:39,060 1 ERROR 2425_ALEXANDRA_SAVU_10227633 odoo.modules.registry: Failed to load registry 
odoodock-web-1     | Traceback (most recent call last):
odoodock-web-1     |   File "/usr/lib/python3/dist-packages/odoo/modules/registry.py", line 63, in __new__
odoodock-web-1     |     return cls.registries[db_name]
odoodock-web-1     |   File "/usr/lib/python3/dist-packages/odoo/tools/func.py", line 71, in wrapper
odoodock-web-1     |     return func(self, *args, **kwargs)
odoodock-web-1     |   File "/usr/lib/python3/dist-packages/odoo/tools/lru.py", line 34, in __getitem__
odoodock-web-1     |     a = self.d[obj]
odoodock-web-1     | KeyError: '2425_ALEXANDRA_SAVU_10227633'
odoodock-web-1     | 
odoodock-web-1     | During handling of the above exception, another exception occurred:
odoodock-web-1     | 
odoodock-web-1     | Traceback (most recent call last):
odoodock-web-1     |   File "/usr/lib/python3/dist-packages/odoo/modules/registry.py", line 89, in new
odoodock-web-1     |     odoo.modules.load_modules(registry._db, force_demo, status, update_module)
odoodock-web-1     |   File "/usr/lib/python3/dist-packages/odoo/modules/loading.py", line 464, in load_modules
odoodock-web-1     |     registry.setup_models(cr)
odoodock-web-1     |   File "/usr/lib/python3/dist-packages/odoo/modules/registry.py", line 276, in setup_models
odoodock-web-1     |     model._setup_fields()
odoodock-web-1     |   File "/usr/lib/python3/dist-packages/odoo/models.py", line 2852, in _setup_fields
odoodock-web-1     |     field.setup_full(self)
odoodock-web-1     |   File "/usr/lib/python3/dist-packages/odoo/fields.py", line 418, in setup_full
odoodock-web-1     |     self._setup_regular_full(model)
odoodock-web-1     |   File "/usr/lib/python3/dist-packages/odoo/fields.py", line 3128, in _setup_regular_full
odoodock-web-1     |     invf = comodel._fields[self.inverse_name]
odoodock-web-1     | KeyError: 'receta_id'
odoodock-web-1     | 2025-02-03 10:57:39,080 1 INFO 2425_ALEXANDRA_SAVU_10227633 werkzeug: 172.18.0.1 - - [03/Feb/2025 10:57:39] "GET /web HTTP/1.1" 500 - 12 0.056 0.768
odoodock-web-1     | Traceback (most recent call last):
odoodock-web-1     |   File "/usr/lib/python3/dist-packages/odoo/service/wsgi_server.py", line 113, in application
odoodock-web-1     |     return application_unproxied(environ, start_response)
odoodock-web-1     |   File "/usr/lib/python3/dist-packages/odoo/service/wsgi_server.py", line 88, in application_unproxied
odoodock-web-1     |     result = odoo.http.root(environ, start_response)
odoodock-web-1     |   File "/usr/lib/python3/dist-packages/odoo/http.py", line 1298, in __call__
odoodock-web-1     |     return self.dispatch(environ, start_response)
odoodock-web-1     |   File "/usr/lib/python3/dist-packages/odoo/http.py", line 1264, in __call__
odoodock-web-1     |     return self.app(environ, start_wrapped)
odoodock-web-1     |   File "/usr/lib/python3/dist-packages/werkzeug/wsgi.py", line 766, in __call__
odoodock-web-1     |     return self.app(environ, start_response)
odoodock-web-1     |   File "/usr/lib/python3/dist-packages/odoo/http.py", line 1471, in dispatch
odoodock-web-1     |     odoo.registry(db).check_signaling()
odoodock-web-1     |   File "/usr/lib/python3/dist-packages/odoo/__init__.py", line 104, in registry
odoodock-web-1     |     return modules.registry.Registry(database_name)
odoodock-web-1     |   File "/usr/lib/python3/dist-packages/odoo/modules/registry.py", line 65, in __new__
odoodock-web-1     |     return cls.new(db_name)
odoodock-web-1     |   File "/usr/lib/python3/dist-packages/odoo/modules/registry.py", line 89, in new
odoodock-web-1     |     odoo.modules.load_modules(registry._db, force_demo, status, update_module)
odoodock-web-1     |   File "/usr/lib/python3/dist-packages/odoo/modules/loading.py", line 464, in load_modules
odoodock-web-1     |     registry.setup_models(cr)
odoodock-web-1     |   File "/usr/lib/python3/dist-packages/odoo/modules/registry.py", line 276, in setup_models
odoodock-web-1     |     model._setup_fields()
odoodock-web-1     |   File "/usr/lib/python3/dist-packages/odoo/models.py", line 2852, in _setup_fields
odoodock-web-1     |     field.setup_full(self)
odoodock-web-1     |   File "/usr/lib/python3/dist-packages/odoo/fields.py", line 418, in setup_full
odoodock-web-1     |     self._setup_regular_full(model)
odoodock-web-1     |   File "/usr/lib/python3/dist-packages/odoo/fields.py", line 3128, in _setup_regular_full
odoodock-web-1     |     invf = comodel._fields[self.inverse_name]
odoodock-web-1     | KeyError: 'receta_id'
odoodock-web-1     | 2025-02-03 10:57:39,325 1 INFO ? werkzeug: 172.18.0.1 - - [03/Feb/2025 10:57:39] "GET /web?__debugger__=yes&cmd=resource&f=style.css HTTP/1.1" 200 - - - -
odoodock-web-1     | 2025-02-03 10:57:39,359 1 INFO ? werkzeug: 172.18.0.1 - - [03/Feb/2025 10:57:39] "GET /web?__debugger__=yes&cmd=resource&f=debugger.js HTTP/1.1" 200 - - - -
odoodock-web-1     | 2025-02-03 10:57:39,379 1 INFO ? werkzeug: 172.18.0.1 - - [03/Feb/2025 10:57:39] "GET /web?__debugger__=yes&cmd=resource&f=jquery.js HTTP/1.1" 200 - - - -
odoodock-web-1     | 2025-02-03 10:57:39,667 1 INFO ? werkzeug: 172.18.0.1 - - [03/Feb/2025 10:57:39] "GET /web?__debugger__=yes&cmd=resource&f=console.png HTTP/1.1" 200 - - - -
